Workbook

Sheet Leia-me
A1: Matriz de decisão multicritério — modelos de estoque MRO (cenário genérico)
A3: Para que serve: reproduz os cálculos da página "Critérios e matriz de decisão" da documentação do Grupo 02 (Entregável 2).
A4: Aplicação genérica: não usa dados da Atvos e não é recomendação para o case real.
A6: Como usar
A7: 1. Células em azul com fundo amarelo são entradas: julgamentos do AHP, notas, premissas. Altere apenas essas células.
A8: 2. Células em preto são fórmulas; células em verde trazem valores de outra aba. Não altere essas células.
A9: 3. Aba AHP: os julgamentos par a par geram os pesos e a razão de consistência (CR). CR abaixo de 0,10 indica julgamentos consistentes.
A10: 4. Aba Matriz: notas de 1 a 5 (ver aba Escala), resultado ponderado, filtro eliminatório e posição, nos cenários base e de rede concentrada.
A11: 5. Aba Sensibilidade: variação de ±10 p.p. em cada peso e varredura do peso do capital imobilizado.
A13: Ordem das abas
A14: Premissas → AHP → Escala → Matriz → Sensibilidade
A16: Limitações
... A24: Documentação do Grupo 02: https://agrotech-inteli-ati.github.io/2026_02_TRAINEE_EDUCACIONAL_02/

Sheet Premissas
A1: Premissas do cenário genérico
A3: Premissa | B3: Valor | C3: Unidade | D3: Origem
A4: Número de usinas da rede | B4: 24 | C4: usinas | D4: Números-base do projeto (Raízen, 31/03/2026)
A5: Grupos regionais | B5: 4 | C5: grupos | D5: Premissa dos autores
A6: Distância da usina ao pool regional | B6: 150 | C6: km | D6: Premissa (página SIPOC, Tabela 3)
A7: Distância da usina ao CD central — cenário base | B7: 600 | C7: km | D7: Premissa (página SIPOC, Tabela 3)
A8: Distância da usina ao CD central — rede concentrada | B8: 100 | C8: km | D8: Premissa do cenário contrastante
A9: Tempo tolerável de parada (limite do filtro) | B9: 8 | C9: h | D9: Premissa (página SIPOC)
A10: Velocidade média do transporte rodoviário | B10: 60 | C10: km/h | D10: Premissa (página SIPOC), inclui paradas
A11: Tempo fora do transporte (ordem, solicitação, separação, recebimento) | B11: 4 | C11: h | D11: Premissa (página SIPOC, Tabela 3: 1 + 1 + 1 + 1 h)
A12: Tempo de atendimento com o item na própria usina | B12: 2 | C12: h | D12: Premissa (página SIPOC, Tabela 3)
A13: Correlação das demandas — sobressalentes de falha aleatória | B13: 0.1 | C13: — | D13: Premissa (página Modelos, Tabela 4)
A14: Correlação das demandas — itens de desgaste | B14: 0.7 | C14: — | D14: Premissa (página Modelos, Tabela 4)

Sheet AHP
A1: AHP — comparação par a par dos critérios (escala de Saaty, 1 a 9)
A2: Leia cada célula como "o critério da linha é X vezes mais importante que o da coluna". Edite apenas o triângulo superior (azul).
A3: Critério | B3: C1 | C3: C2 | D3: C3 | E3: C4 | F3: C5 | G3: C6 | H3: Média geométrica | I3: Peso | J3: A · w | K3: (A · w) ÷ w
A4: C1. Disponibilidade para itens críticos | B4: 1 | C4: 3 | D4: 5 | E4: 5 | F4: 5 | G4: 3 | H4: =GEOMEAN(B4:G4) -> 3.2249681 | I4: =H4/SUM($H$4:$H$9) -> 0.41881842 | J4: =B4*$I$4+C4*$I$5+D4*$I$6+E4*$I$7+F4*$I$8+G4*$I$9 -> 2.5755212 | K4: =J4/I4 -> 6.1494936
A5: C2. Capital imobilizado | B5: =1/C4 -> 0.33333333 | C5: 1 | D5: 3 | E5: 3 | F5: 3 | G5: 1 | H5: =GEOMEAN(B5:G5) -> 1.4422496 | I5: =H5/SUM($H$4:$H$9) -> 0.18730129 | J5: =B5*$I$4+C5*$I$5+D5*$I$6+E5*$I$7+F5*$I$8+G5*$I$9 -> 1.1339457 | K5: =J5/I5 -> 6.0541267
A6: C3. Custo de transporte | B6: =1/D4 -> 0.2 | C6: =1/D5 -> 0.33333333 | D6: 1 | E6: 1 | F6: 1 | G6: 0.33333333 | H6: =GEOMEAN(B6:G6) -> 0.53023035 | I6: =H6/SUM($H$4:$H$9) -> 0.068859669 | J6: =B6*$I$4+C6*$I$5+D6*$I$6+E6*$I$7+F6*$I$8+G6*$I$9 -> 0.41521022 | K6: =J6/I6 -> 6.0298027
A7: C4. Governança | B7: =1/E4 -> 0.2 | C7: =1/E5 -> 0.33333333 | D7: =1/E6 -> 1 | E7: 1 | F7: 1 | G7: 0.33333333 | H7: =GEOMEAN(B7:G7) -> 0.53023035 | I7: =H7/SUM($H$4:$H$9) -> 0.068859669 | J7: =B7*$I$4+C7*$I$5+D7*$I$6+E7*$I$7+F7*$I$8+G7*$I$9 -> 0.41521022 | K7: =J7/I7 -> 6.0298027
A8: C5. Escala de armazenagem | B8: =1/F4 -> 0.2 | C8: =1/F5 -> 0.33333333 | D8: =1/F6 -> 1 | E8: =1/F7 -> 1 | F8: 1 | G8: 0.33333333 | H8: =GEOMEAN(B8:G8) -> 0.53023035 | I8: =H8/SUM($H$4:$H$9) -> 0.068859669 | J8: =B8*$I$4+C8*$I$5+D8*$I$6+E8*$I$7+F8*$I$8+G8*$I$9 -> 0.41521022 | K8: =J8/I8 -> 6.0298027
A9: C6. Resiliência | B9: =1/G4 -> 0.33333333 | C9: =1/G5 -> 1 | D9: =1/G6 -> 3 | E9: =1/G7 -> 3 | F9: =1/G8 -> 3 | G9: 1 | H9: =GEOMEAN(B9:G9) -> 1.4422496 | I9: =H9/SUM($H$4:$H$9) -> 0.18730129 | J9: =B9*$I$4+C9*$I$5+D9*$I$6+E9*$I$7+F9*$I$8+G9*$I$9 -> 1.1339457 | K9: =J9/I9 -> 6.0541267
H10: Total | I10: =SUM(I4:I9) -> 1
A12: λ máximo | B12: =AVERAGE(K4:K9) -> 6.0578592
A13: n (número de critérios) | B13: 6
A14: Índice de consistência (CI) | B14: =(B12-B13)/(B13-1) -> 0.011571836
A15: Índice aleatório (RI, Saaty, n = 6) | B15: 1.24
A16: Razão de consistência (CR = CI ÷ RI) | B16: =B14/B15 -> 0.0093321261
A17: Situação | B17: =IF(B16<0.1,"Consistente (CR < 0,10)","Revisar julgamentos (CR ≥ 0,10)") -> Consistente (CR < 0,10)
A19: Escala de Saaty
A20: 1 | B20: Igual importância
A21: 3 | B21: Importância moderada
A22: 5 | B22: Importância forte
A23: 7 | B23: Importância muito forte
A24: 9 | B24: Importância extrema
A25: 2, 4, 6, 8 | B25: Valores intermediários
A26: 1/3, 1/5 ... | B26: O critério da coluna é mais importante que o da linha
A28: Justificativa dos julgamentos
A29: Par | B29: Julgamento | C29: Justificativa
A30: C1 × C2 | B30: =C4 -> 3 | C30: Disponibilidade é moderadamente mais importante que capital: a falta de peça crítica para a moagem na safra.
A31: C1 × C3 | B31: =D4 -> 5 | C31: Disponibilidade é fortemente mais importante que frete: o custo de parada supera o custo de transporte.
A32: C1 × C4 | B32: =E4 -> 5 | C32: Disponibilidade é fortemente mais importante que governança: controle não compensa usina parada.
A33: C1 × C5 | B33: =F4 -> 5 | C33: Disponibilidade é fortemente mais importante que escala de armazenagem.
A34: C1 × C6 | B34: =G4 -> 3 | C34: Disponibilidade é moderadamente mais importante que resiliência: ambas protegem a operação, mas a quebra é o evento mais frequente.
A35: C2 × C3 | B35: =D5 -> 3 | C35: Capital é moderadamente mais importante que frete, dada a pressão de caixa (recuperação extrajudicial).
A36: C2 × C4 | B36: =E5 -> 3 | C36: Capital é moderadamente mais importante que governança.
A37: C2 × C5 | B37: =F5 -> 3 | C37: Capital é moderadamente mais importante que escala.
A38: C2 × C6 | B38: =G5 -> 1 | C38: Capital e resiliência têm a mesma importância: um protege o caixa, o outro a continuidade.
A39: C3 × C4 | B39: =E6 -> 1 | C39: Frete e governança têm a mesma importância.
A40: C3 × C5 | B40: =F6 -> 1 | C40: Frete e escala têm a mesma importância.
A41: C3 × C6 | B41: =G6 -> 0.33333333 | C41: Resiliência é moderadamente mais importante que frete (rotas sujeitas a chuvas e bloqueios).
A42: C4 × C5 | B42: =F7 -> 1 | C42: Governança e escala têm a mesma importância.
A43: C4 × C6 | B43: =G7 -> 0.33333333 | C43: Resiliência é moderadamente mais importante que governança.
...

Sheet Escala
A1: Escala ancorada de avaliação (1 a 5)
A2: Cada nota tem um significado definido por critério. Regra para notas intermediárias: não se usam notas fracionadas.
A3: Critério | B3: 5 | C3: 4 | D3: 3 | E3: 2 | F3: 1
A4: C1. Disponibilidade para itens críticos | B4: Tempo de atendimento ao item crítico de até 2 h | C4: Todos os itens críticos dentro do limite de parada (8 h) | D4: Até 12 h | E4: Até 2 vezes o limite (até 16 h) | F4: Mais de 2 vezes o limite
A5: C2. Capital imobilizado | B5: Redução do estoque de segurança de 60% ou mais | C5: 40% a 60% | D5: 20% a 40% | E5: 5% a 20% | F5: Menos de 5% (sem compartilhamento)
A6: C3. Custo de transporte | B6: Abastecimento consolidado e sem transferências longas | C6: Abastecimento consolidado; transferências curtas (até 150 km) para parte dos itens | D6: Entregas fracionadas em cada unidade, sem transferências | E6: Abastecimento consolidado, mas transferências longas para todos os itens | F6: Entregas fracionadas e transferências longas
A7: C4. Governança | B7: Um único ponto de estoque e cadastro | C7: Poucos pontos (até 5) com cadastro único | D7: Vários pontos com cadastro único e regras de segmentação | E7: Um ponto por unidade com cadastro corporativo compartilhado | F7: Um ponto por unidade com cadastros independentes
A8: C5. Escala de armazenagem | B8: Um único ponto concentra armazenagem e recebimento | C8: Poucos pontos concentram os itens de maior valor | D8: Parte relevante do volume concentrada | E8: Pequena parte do volume concentrada | F8: Cada unidade armazena e recebe tudo
A9: C6. Resiliência | B9: Interrupção afeta apenas uma unidade | C9: Afeta um grupo regional, com itens críticos protegidos na usina | D9: Afeta um grupo regional inteiro | E9: Afeta toda a rede, com rota curta e alternativas | F9: Afeta toda a rede e depende de rota longa
A11: Nota sobre C5: a negociação de compras é centralizada em todos os modelos (Central de Compras, PLT.02); por isso C5 mede só a escala de armazenagem e recebimento.

Sheet Matriz
A1: Matriz multicritério — resultado ponderado, filtro eliminatório e posição
A3: Cenário base (CD central a 600 km)
A4: Critério | B4: Peso | C4: Centralizado | D4: Descentralizado | E4: Híbrido
A5: C1. Disponibilidade para itens críticos | B5: =AHP!I4 -> 0.41881842 | C5: 2 | D5: 5 | E5: 4
A6: C2. Capital imobilizado | B6: =AHP!I5 -> 0.18730129 | C6: 5 | D6: 1 | E6: 4
A7: C3. Custo de transporte | B7: =AHP!I6 -> 0.068859669 | C7: 2 | D7: 3 | E7: 4
A8: C4. Governança | B8: =AHP!I7 -> 0.068859669 | C8: 5 | D8: 2 | E8: 3
A9: C5. Escala de armazenagem | B9: =AHP!I8 -> 0.068859669 | C9: 5 | D9: 1 | E9: 4
A10: C6. Resiliência | B10: =AHP!I9 -> 0.18730129 | C10: 1 | D10: 5 | E10: 4
A11: Resultado ponderado | B11: =SUM(B5:B10) -> 1 | C11: =SUMPRODUCT($B$5:$B$10,C5:C10) -> 2.7877606 | D11: =SUMPRODUCT($B$5:$B$10,D5:D10) -> 3.6310578 | E11: =SUMPRODUCT($B$5:$B$10,E5:E10) -> 3.9311403
A13: Tempo de atendimento ao item crítico (h) | C13: =Premissas!$B$11+Premissas!$B$7/Premissas!$B$10 -> 14 | D13: =Premissas!$B$12 -> 2 | E13: =MAX(Premissas!$B$12,Premissas!$B$11+Premissas!$B$6/Premissas!$B$10) -> 6.5
A14: Limite do filtro: tempo tolerável de parada (h) | C14: =Premissas!$B$9 -> 8 | D14: =Premissas!$B$9 -> 8 | E14: =Premissas!$B$9 -> 8
A15: Filtro eliminatório | C15: =IF(C13<=C14,"Passa","Não passa") -> Não passa | D15: =IF(D13<=D14,"Passa","Não passa") -> Passa | E15: =IF(E13<=E14,"Passa","Não passa") -> Passa
A16: Posição (entre as que passam no filtro) | C16: =IF(C15="Passa",1+SUMPRODUCT(($C$11:$E$11>C11)*($C$15:$E$15="Passa")),"Eliminada") -> Eliminada | D16: =IF(D15="Passa",1+SUMPRODUCT(($C$11:$E$11>D11)*($C$15:$E$15="Passa")),"Eliminada") -> 2 | E16: =IF(E15="Passa",1+SUMPRODUCT(($C$11:$E$11>E11)*($C$15:$E$15="Passa")),"Eliminada") -> 1
A19: Cenário contrastante: rede concentrada (CD central a 100 km)
A20: Critério | B20: Peso | C20: Centralizado | D20: Descentralizado | E20: Híbrido
A21: C1. Disponibilidade para itens críticos | B21: =AHP!I4 -> 0.41881842 | C21: 4 | D21: 5 | E21: 4
A22: C2. Capital imobilizado | B22: =AHP!I5 -> 0.18730129 | C22: 5 | D22: 1 | E22: 4
A23: C3. Custo de transporte | B23: =AHP!I6 -> 0.068859669 | C23: 4 | D23: 3 | E23: 4
A24: C4. Governança | B24: =AHP!I7 -> 0.068859669 | C24: 5 | D24: 2 | E24: 3
A25: C5. Escala de armazenagem | B25: =AHP!I8 -> 0.068859669 | C25: 5 | D25: 1 | E25: 4
A26: C6. Resiliência | B26: =AHP!I9 -> 0.18730129 | C26: 2 | D26: 5 | E26: 4
A27: Resultado ponderado | B27: =SUM(B21:B26) -> 1 | C27: =SUMPRODUCT($B$21:$B$26,C21:C26) -> 3.950418 | D27: =SUMPRODUCT($B$21:$B$26,D21:D26) -> 3.6310578 | E27: =SUMPRODUCT($B$21:$B$26,E21:E26) -> 3.9311403
A29: Tempo de atendimento ao item crítico (h) | C29: =Premissas!$B$11+Premissas!$B$8/Premissas!$B$10 -> 5.6666667 | D29: =Premissas!$B$12 -> 2 | E29: =MAX(Premissas!$B$12,Premissas!$B$11+Premissas!$B$6/Premissas!$B$10) -> 6.5
A30: Limite do filtro: tempo tolerável de parada (h) | C30: =Premissas!$B$9 -> 8 | D30: =Premissas!$B$9 -> 8 | E30: =Premissas!$B$9 -> 8
A31: Filtro eliminatório | C31: =IF(C29<=C30,"Passa","Não passa") -> Passa | D31: =IF(D29<=D30,"Passa","Não passa") -> Passa | E31: =IF(E29<=E30,"Passa","Não passa") -> Passa
A32: Posição (entre as que passam no filtro) | C32: =IF(C31="Passa",1+SUMPRODUCT(($C$27:$E$27>C27)*($C$31:$E$31="Passa")),"Eliminada") -> 1 | D32: =IF(D31="Passa",1+SUMPRODUCT(($C$27:$E$27>D27)*($C$31:$E$31="Passa")),"Eliminada") -> 3 | E32: =IF(E31="Passa",1+SUMPRODUCT(($C$27:$E$27>E27)*($C$31:$E$31="Passa")),"Eliminada") -> 2
A34: No cenário concentrado, mudam apenas as notas do Centralizado em C1 (4), C3 (4) e C6 (2), porque o CD fica a 100 km das usinas.

Sheet Sensibilidade
A1: Sensibilidade dos resultados aos pesos (cenário base)
A2: Ao alterar o peso de um critério, os demais são reescalados proporcionalmente para somar 100%. O líder considera o filtro eliminatório do cenário base.
A4: Variação de ±10 p.p. em cada peso
A5: Critério (índice) | B5: Variação | C5: C1 | D5: C2 | E5: C3 | F5: C4 | G5: C5 | H5: C6 | I5: Centralizado | J5: Descentralizado | K5: Híbrido | L5: Líder (após filtro)
A6: 1 | B6: -0.1 | C6: =IF(1=$A6,MAX(0,MIN(1,INDEX(AHP!$I$4:$I$9,$A6)+$B6)),INDEX(AHP!$I$4:$I$9,1)*(1-MAX(0,MIN(1,INDEX(AHP!$I$4:$I$9,$A6)+$B6)))/(1-INDEX(AHP!$I$4:$I$9,$A6))) -> 0.31881842 | D6: =IF(2=$A6,MAX(0,MIN(1,INDEX(AHP!$I$4:$I$9,$A6)+$B6)),INDEX(AHP!$I$4:$I$9,2)*(1-MAX(0,MIN(1,INDEX(AHP!$I$4:$I$9,$A6)+$B6)))/(1-INDEX(AHP!$I$4:$I$9,$A6))) -> 0.21952896 | E6: =IF(3=$A6,MAX(0,MIN(1,INDEX(AHP!$I$4:$I$9,$A6)+$B6)),INDEX(AHP!$I$4:$I$9,3)*(1-MAX(0,MIN(1,INDEX(AHP!$I$4:$I$9,$A6)+$B6)))/(1-INDEX(AHP!$I$4:$I$9,$A6))) -> 0.080707888 | F6: =IF(4=$A6,MAX(0,MIN(1,INDEX(AHP!$I$4:$I$9,$A6)+$B6)),INDEX(AHP!$I$4:$I$9,4)*(1-MAX(0,MIN(1,INDEX(AHP!$I$4:$I$9,$A6)+$B6)))/(1-INDEX(AHP!$I$4:$I$9,$A6))) -> 0.080707888 | G6: =IF(5=$A6,MAX(0,MIN(1,INDEX(AHP!$I$4:$I$9,$A6)+$B6)),INDEX(AHP!$I$4:$I$9,5)*(1-MAX(0,MIN(1,INDEX(AHP!$I$4:$I$9,$A6)+$B6)))/(1-INDEX(AHP!$I$4:$I$9,$A6))) -> 0.080707888 | H6: =IF(6=$A6,MAX(0,MIN(1,INDEX(AHP!$I$4:$I$9,$A6)+$B6)),INDEX(AHP!$I$4:$I$9,6)*(1-MAX(0,MIN(1,INDEX(AHP!$I$4:$I$9,$A6)+$B6)))/(1-INDEX(AHP!$I$4:$I$9,$A6))) -> 0.21952896 | I6: =C6*Matriz!C$5+D6*Matriz!C$6+E6*Matriz!C$7+F6*Matriz!C$8+G6*Matriz!C$9+H6*Matriz!C$10 -> 2.9233052 | J6: =C6*Matriz!D$5+D6*Matriz!D$6+E6*Matriz!D$7+F6*Matriz!D$8+G6*Matriz!D$9+H6*Matriz!D$10 -> 3.3955132 | K6: =C6*Matriz!E$5+D6*Matriz!E$6+E6*Matriz!E$7+F6*Matriz!E$8+G6*Matriz!E$9+H6*Matriz!E$10 -> 3.9192921 | L6: =IF(AND(IF(Matriz!$C$15="Passa",I6,-1)>=IF(Matriz!$D$15="Passa",J6,-1),IF(Matriz!$C$15="Passa",I6,-1)>=IF(Matriz!$E$15="Passa",K6,-1)),$I$5,IF(IF(Matriz!$D$15="Passa",J6,-1)>=IF(Matriz!$E$15="Passa",K6,-1),$J$5,$K$5)) -> Híbrido
A7: 1 | B7: 0.1 | C7: =IF(1=$A7,MAX(0,MIN(1,INDEX(AHP!$I$4:$I$9,$A7)+$B7)),INDEX(AHP!$I$4:$I$9,1)*(1-MAX(0,MIN(1,INDEX(AHP!$I$4:$I$9,$A7)+$B7)))/(1-INDEX(AHP!$I$4:$I$9,$A7))) -> 0.51881842 | D7: =IF(2=$A7,MAX(0,MIN(1,INDEX(AHP!$I$4:$I$9,$A7)+$B7)),INDEX(AHP!$I$4:$I$9,2)*(1-MAX(0,MIN(1,INDEX(AHP!$I$4:$I$9,$A7)+$B7)))/(1-INDEX(AHP!$I$4:$I$9,$A7))) -> 0.15507362 | E7: =IF(3=$A7,MAX(0,MIN(1,INDEX(AHP!$I$4:$I$9,$A7)+$B7)),INDEX(AHP!$I$4:$I$9,3)*(1-MAX(0,MIN(1,INDEX(AHP!$I$4:$I$9,$A7)+$B7)))/(1-INDEX(AHP!$I$4:$I$9,$A7))) -> 0.057011449 | F7: =IF(4=$A7,MAX(0,MIN(1,INDEX(AHP!$I$4:$I$9,$A7)+$B7)),INDEX(AHP!$I$4:$I$9,4)*(1-MAX(0,MIN(1,INDEX(AHP!$I$4:$I$9,$A7)+$B7)))/(1-INDEX(AHP!$I$4:$I$9,$A7))) -> 0.057011449 | G7: =IF(5=$A7,MAX(0,MIN(1,INDEX(AHP!$I$4:$I$9,$A7)+$B7)),INDEX(AHP!$I$4:$I$9,5)*(1-MAX(0,MIN(1,INDEX(AHP!$I$4:$I$9,$A7)+$B7)))/(1-INDEX(AHP!$I$4:$I$9,$A7))) -> 0.057011449 | H7: =IF(6=$A7,MAX(0,MIN(1,INDEX(AHP!$I$4:$I$9,$A7)+$B7)),INDEX(AHP!$I$4:$I$9,6)*(1-MAX(0,MIN(1,INDEX(AHP!$I$4:$I$9,$A7)+$B7)))/(1-INDEX(AHP!$I$4:$I$9,$A7))) -> 0.15507362 | I7: =C7*Matriz!C$5+D7*Matriz!C$6+E7*Matriz!C$7+F7*Matriz!C$8+G7*Matriz!C$9+H7*Matriz!C$10 -> 2.6522159 | J7: =C7*Matriz!D$5+D7*Matriz!D$6+E7*Matriz!D$7+F7*Matriz!D$8+G7*Matriz!D$9+H7*Matriz!D$10 -> 3.8666025 | K7: =C7*Matriz!E$5+D7*Matriz!E$6+E7*Matriz!E$7+F7*Matriz!E$8+G7*Matriz!E$9+H7*Matriz!E$10 -> 3.9429886 | L7: =IF(AND(IF(Matriz!$C$15="Passa",I7,-1)>=IF(Matriz!$D$15="Passa",J7,-1),IF(Matriz!$C$15="Passa",I7,-1)>=IF(Matriz!$E$15="Passa",K7,-1)),$I$5,IF(IF(Matriz!$D$15="Passa",J7,-1)>=IF(Matriz!$E$15="Passa",K7,-1),$J$5,$K$5)) -> Híbrido
A8: 2 | B8: -0.1 | C8: =IF(1=$A8,MAX(0,MIN(1,INDEX(AHP!$I$4:$I$9,$A8)+$B8)),INDEX(AHP!$I$4:$I$9,1)*(1-MAX(0,MIN(1,INDEX(AHP!$I$4:$I$9,$A8)+$B8)))/(1-INDEX(AHP!$I$4:$I$9,$A8))) -> 0.47035269 | D8: =IF(2=$A8,MAX(0,MIN(1,INDEX(AHP!$I$4:$I$9,$A8)+$B8)),INDEX(AHP!$I$4:$I$9,2)*(1-MAX(0,MIN(1,INDEX(AHP!$I$4:$I$9,$A8)+$B8)))/(1-INDEX(AHP!$I$4:$I$9,$A8))) -> 0.087301289 | E8: =IF(3=$A8,MAX(0,MIN(1,INDEX(AHP!$I$4:$I$9,$A8)+$B8)),INDEX(AHP!$I$4:$I$9,3)*(1-MAX(0,MIN(1,INDEX(AHP!$I$4:$I$9,$A8)+$B8)))/(1-INDEX(AHP!$I$4:$I$9,$A8))) -> 0.077332633 | F8: =IF(4=$A8,MAX(0,MIN(1,INDEX(AHP!$I$4:$I$9,$A8)+$B8)),INDEX(AHP!$I$4:$I$9,4)*(1-MAX(0,MIN(1,INDEX(AHP!$I$4:$I$9,$A8)+$B8)))/(1-INDEX(AHP!$I$4:$I$9,$A8))) -> 0.077332633 | G8: =IF(5=$A8,MAX(0,MIN(1,INDEX(AHP!$I$4:$I$9,$A8)+$B8)),INDEX(AHP!$I$4:$I$9,5)*(1-MAX(0,MIN(1,INDEX(AHP!$I$4:$I$9,$A8)+$B8)))/(1-INDEX(AHP!$I$4:$I$9,$A8))) -> 0.077332633 | H8: =IF(6=$A8,MAX(0,MIN(1,INDEX(AHP!$I$4:$I$9,$A8)+$B8)),INDEX(AHP!$I$4:$I$9,6)*(1-MAX(0,MIN(1,INDEX(AHP!$I$4:$I$9,$A8)+$B8)))/(1-INDEX(AHP!$I$4:$I$9,$A8))) -> 0.21034812 | I8: =C8*Matriz!C$5+D8*Matriz!C$6+E8*Matriz!C$7+F8*Matriz!C$8+G8*Matriz!C$9+H8*Matriz!C$10 -> 2.5155515 | J8: =C8*Matriz!D$5+D8*Matriz!D$6+E8*Matriz!D$7+F8*Matriz!D$8+G8*Matriz!D$9+H8*Matriz!D$10 -> 3.9548011 | K8: =C8*Matriz!E$5+D8*Matriz!E$6+E8*Matriz!E$7+F8*Matriz!E$8+G8*Matriz!E$9+H8*Matriz!E$10 -> 3.9226674 | L8: =IF(AND(IF(Matriz!$C$15="Passa",I8,-1)>=IF(Matriz!$D$15="Passa",J8,-1),IF(Matriz!$C$15="Passa",I8,-1)>=IF(Matriz!$E$15="Passa",K8,-1)),$I$5,IF(IF(Matriz!$D$15="Passa",J8,-1)>=IF(Matriz!$E$15="Passa",K8,-1),$J$5,$K$5)) -> Descentralizado
A9: 2 | B9: 0.1 | C9: =IF(1=$A9,MAX(0,MIN(1,INDEX(AHP!$I$4:$I$9,$A9)+$B9)),INDEX(AHP!$I$4:$I$9,1)*(1-MAX(0,MIN(1,INDEX(AHP!$I$4:$I$9,$A9)+$B9)))/(1-INDEX(AHP!$I$4:$I$9,$A9))) -> 0.36728414 | D9: =IF(2=$A9,MAX(0,MIN(1,INDEX(AHP!$I$4:$I$9,$A9)+$B9)),INDEX(AHP!$I$4:$I$9,2)*(1-MAX(0,MIN(1,INDEX(AHP!$I$4:$I$9,$A9)+$B9)))/(1-INDEX(AHP!$I$4:$I$9,$A9))) -> 0.28730129 | E9: =IF(3=$A9,MAX(0,MIN(1,INDEX(AHP!$I$4:$I$9,$A9)+$B9)),INDEX(AHP!$I$4:$I$9,3)*(1-MAX(0,MIN(1,INDEX(AHP!$I$4:$I$9,$A9)+$B9)))/(1-INDEX(AHP!$I$4:$I$9,$A9))) -> 0.060386705 | F9: =IF(4=$A9,MAX(0,MIN(1,INDEX(AHP!$I$4:$I$9,$A9)+$B9)),INDEX(AHP!$I$4:$I$9,4)*(1-MAX(0,MIN(1,INDEX(AHP!$I$4:$I$9,$A9)+$B9)))/(1-INDEX(AHP!$I$4:$I$9,$A9))) -> 0.060386705 | G9: =IF(5=$A9,MAX(0,MIN(1,INDEX(AHP!$I$4:$I$9,$A9)+$B9)),INDEX(AHP!$I$4:$I$9,5)*(1-MAX(0,MIN(1,INDEX(AHP!$I$4:$I$9,$A9)+$B9)))/(1-INDEX(AHP!$I$4:$I$9,$A9))) -> 0.060386705 | H9: =IF(6=$A9,MAX(0,MIN(1,INDEX(AHP!$I$4:$I$9,$A9)+$B9)),INDEX(AHP!$I$4:$I$9,6)*(1-MAX(0,MIN(1,INDEX(AHP!$I$4:$I$9,$A9)+$B9)))/(1-INDEX(AHP!$I$4:$I$9,$A9))) -> 0.16425446 | I9: =C9*Matriz!C$5+D9*Matriz!C$6+E9*Matriz!C$7+F9*Matriz!C$8+G9*Matriz!C$9+H9*Matriz!C$10 -> 3.0599696 | J9: =C9*Matriz!D$5+D9*Matriz!D$6+E9*Matriz!D$7+F9*Matriz!D$8+G9*Matriz!D$9+H9*Matriz!D$10 -> 3.3073145 | K9: =C9*Matriz!E$5+D9*Matriz!E$6+E9*Matriz!E$7+F9*Matriz!E$8+G9*Matriz!E$9+H9*Matriz!E$10 -> 3.9396133 | L9: =IF(AND(IF(Matriz!$C$15="Passa",I9,-1)>=IF(Matriz!$D$15="Passa",J9,-1),IF(Matriz!$C$15="Passa",I9,-1)>=IF(Matriz!$E$15="Passa",K9,-1)),$I$5,IF(IF(Matriz!$D$15="Passa",J9,-1)>=IF(Matriz!$E$15="Passa",K9,-1),$J$5,$K$5)) -> Híbrido
A10: 3 | B10: -0.1 | C10: =IF(1=$A10,MAX(0,MIN(1,INDEX(AHP!$I$4:$I$9,$A10)+$B10)),INDEX(AHP!$I$4:$I$9,1)*(1-MAX(0,MIN(1,INDEX(AHP!$I$4:$I$9,$A10)+$B10)))/(1-INDEX(AHP!$I$4:$I$9,$A10))) -> 0.44979087 | D10: =IF(2=$A10,MAX(0,MIN(1,INDEX(AHP!$I$4:$I$9,$A10)+$B10)),INDEX(AHP!$I$4:$I$9,2)*(1-MAX(0,MIN(1,INDEX(AHP!$I$4:$I$9,$A10)+$B10)))/(1-INDEX(AHP!$I$4:$I$9,$A10))) -> 0.20115259 | E10: =IF(3=$A10,MAX(0,MIN(1,INDEX(AHP!$I$4:$I$9,$A10)+$B10)),INDEX(AHP!$I$4:$I$9,3)*(1-MAX(0,MIN(1,INDEX(AHP!$I$4:$I$9,$A10)+$B10)))/(1-INDEX(AHP!$I$4:$I$9,$A10))) -> 0 | F10: =IF(4=$A10,MAX(0,MIN(1,INDEX(AHP!$I$4:$I$9,$A10)+$B10)),INDEX(AHP!$I$4:$I$9,4)*(1-MAX(0,MIN(1,INDEX(AHP!$I$4:$I$9,$A10)+$B10)))/(1-INDEX(AHP!$I$4:$I$9,$A10))) -> 0.073951977 | G10: =IF(5=$A10,MAX(0,MIN(1,INDEX(AHP!$I$4:$I$9,$A10)+$B10)),INDEX(AHP!$I$4:$I$9,5)*(1-MAX(0,MIN(1,INDEX(AHP!$I$4:$I$9,$A10)+$B10)))/(1-INDEX(AHP!$I$4:$I$9,$A10))) -> 0.073951977 | H10: =IF(6=$A10,MAX(0,MIN(1,INDEX(AHP!$I$4:$I$9,$A10)+$B10)),INDEX(AHP!$I$4:$I$9,6)*(1-MAX(0,MIN(1,INDEX(AHP!$I$4:$I$9,$A10)+$B10)))/(1-INDEX(AHP!$I$4:$I$9,$A10))) -> 0.20115259 | I10: =C10*Matriz!C$5+D10*Matriz!C$6+E10*Matriz!C$7+F10*Matriz!C$8+G10*Matriz!C$9+H10*Matriz!C$10 -> 2.846017 | J10: =C10*Matriz!D$5+D10*Matriz!D$6+E10*Matriz!D$7+F10*Matriz!D$8+G10*Matriz!D$9+H10*Matriz!D$10 -> 3.6777258 | K10: =C10*Matriz!E$5+D10*Matriz!E$6+E10*Matriz!E$7+F10*Matriz!E$8+G10*Matriz!E$9+H10*Matriz!E$10 -> 3.926048 | L10: =IF(AND(IF(Matriz!$C$15="Passa",I10,-1)>=IF(Matriz!$D$15="Passa",J10,-1),IF(Matriz!$C$15="Passa",I10,-1)>=IF(Matriz!$E$15="Passa",K10,-1)),$I$5,IF(IF(Matriz!$D$15="Passa",J10,-1)>=IF(Matriz!$E$15="Passa",K10,-1),$J$5,$K$5)) -> Híbrido
A11: 3 | B11: 0.1 | C11: =IF(1=$A11,MAX(0,MIN(1,INDEX(AHP!$I$4:$I$9,$A11)+$B11)),INDEX(AHP!$I$4:$I$9,1)*(1-MAX(0,MIN(1,INDEX(AHP!$I$4:$I$9,$A11)+$B11)))/(1-INDEX(AHP!$I$4:$I$9,$A11))) -> 0.37383933 | D11: =IF(2=$A11,MAX(0,MIN(1,INDEX(AHP!$I$4:$I$9,$A11)+$B11)),INDEX(AHP!$I$4:$I$9,2)*(1-MAX(0,MIN(1,INDEX(AHP!$I$4:$I$9,$A11)+$B11)))/(1-INDEX(AHP!$I$4:$I$9,$A11))) -> 0.16718603 | E11: =IF(3=$A11,MAX(0,MIN(1,INDEX(AHP!$I$4:$I$9,$A11)+$B11)),INDEX(AHP!$I$4:$I$9,3)*(1-MAX(0,MIN(1,INDEX(AHP!$I$4:$I$9,$A11)+$B11)))/(1-INDEX(AHP!$I$4:$I$9,$A11))) -> 0.16885967 | F11: =IF(4=$A11,MAX(0,MIN(1,INDEX(AHP!$I$4:$I$9,$A11)+$B11)),INDEX(AHP!$I$4:$I$9,4)*(1-MAX(0,MIN(1,INDEX(AHP!$I$4:$I$9,$A11)+$B11)))/(1-INDEX(AHP!$I$4:$I$9,$A11))) -> 0.061464471 | G11: =IF(5=$A11,MAX(0,MIN(1,INDEX(AHP!$I$4:$I$9,$A11)+$B11)),INDEX(AHP!$I$4:$I$9,5)*(1-MAX(0,MIN(1,INDEX(AHP!$I$4:$I$9,$A11)+$B11)))/(1-INDEX(AHP!$I$4:$I$9,$A11))) -> 0.061464471 | H11: =IF(6=$A11,MAX(0,MIN(1,INDEX(AHP!$I$4:$I$9,$A11)+$B11)),INDEX(AHP!$I$4:$I$9,6)*(1-MAX(0,MIN(1,INDEX(AHP!$I$4:$I$9,$A11)+$B11)))/(1-INDEX(AHP!$I$4:$I$9,$A11))) -> 0.16718603 | I11: =C11*Matriz!C$5+D11*Matriz!C$6+E11*Matriz!C$7+F11*Matriz!C$8+G11*Matriz!C$9+H11*Matriz!C$10 -> 2.7031589 | J11: =C11*Matriz!D$5+D11*Matriz!D$6+E11*Matriz!D$7+F11*Matriz!D$8+G11*Matriz!D$9+H11*Matriz!D$10 -> 3.5632852 | K11: =C11*Matriz!E$5+D11*Matriz!E$6+E11*Matriz!E$7+F11*Matriz!E$8+G11*Matriz!E$9+H11*Matriz!E$10 -> 3.9385355 | L11: =IF(AND(IF(Matriz!$C$15="Passa",I11,-1)>=IF(Matriz!$D$15="Passa",J11,-1),IF(Matriz!$C$15="Passa",I11,-1)>=IF(Matriz!$E$15="Passa",K11,-1)),$I$5,IF(IF(Matriz!$D$15="Passa",J11,-1)>=IF(Matriz!$E$15="Passa",K11,-1),$J$5,$K$5)) -> Híbrido
A12: 4 | B12: -0.1 | C12: =IF(1=$A12,MAX(0,MIN(1,INDEX(AHP!$I$4:$I$9,$A12)+$B12)),INDEX(AHP!$I$4:$I$9,1)*(1-MAX(0,MIN(1,INDEX(AHP!$I$4:$I$9,$A12)+$B12)))/(1-INDEX(AHP!$I$4:$I$9,$A12))) -> 0.44979087 | D12: =IF(2=$A12,MAX(0,MIN(1,INDEX(AHP!$I$4:$I$9,$A12)+$B12)),INDEX(AHP!$I$4:$I$9,2)*(1-MAX(0,MIN(1,INDEX(AHP!$I$4:$I$9,$A12)+$B12)))/(1-INDEX(AHP!$I$4:$I$9,$A12))) -> 0.20115259 | E12: =IF(3=$A12,MAX(0,MIN(1,INDEX(AHP!$I$4:$I$9,$A12)+$B12)),INDEX(AHP!$I$4:$I$9,3)*(1-MAX(0,MIN(1,INDEX(AHP!$I$4:$I$9,$A12)+$B12)))/(1-INDEX(AHP!$I$4:$I$9,$A12))) -> 0.073951977 | F12: =IF(4=$A12,MAX(0,MIN(1,INDEX(AHP!$I$4:$I$9,$A12)+$B12)),INDEX(AHP!$I$4:$I$9,4)*(1-MAX(0,MIN(1,INDEX(AHP!$I$4:$I$9,$A12)+$B12)))/(1-INDEX(AHP!$I$4:$I$9,$A12))) -> 0 | G12: =IF(5=$A12,MAX(0,MIN(1,INDEX(AHP!$I$4:$I$9,$A12)+$B12)),INDEX(AHP!$I$4:$I$9,5)*(1-MAX(0,MIN(1,INDEX(AHP!$I$4:$I$9,$A12)+$B12)))/(1-INDEX(AHP!$I$4:$I$9,$A12))) -> 0.073951977 | H12: =IF(6=$A12,MAX(0,MIN(1,INDEX(AHP!$I$4:$I$9,$A12)+$B12)),INDEX(AHP!$I$4:$I$9,6)*(1-MAX(0,MIN(1,INDEX(AHP!$I$4:$I$9,$A12)+$B12)))/(1-INDEX(AHP!$I$4:$I$9,$A12))) -> 0.20115259 | I12: =C12*Matriz!C$5+D12*Matriz!C$6+E12*Matriz!C$7+F12*Matriz!C$8+G12*Matriz!C$9+H12*Matriz!C$10 -> 2.6241611 | J12: =C12*Matriz!D$5+D12*Matriz!D$6+E12*Matriz!D$7+F12*Matriz!D$8+G12*Matriz!D$9+H12*Matriz!D$10 -> 3.7516778 | K12: =C12*Matriz!E$5+D12*Matriz!E$6+E12*Matriz!E$7+F12*Matriz!E$8+G12*Matriz!E$9+H12*Matriz!E$10 -> 4 | L12: =IF(AND(IF(Matriz!$C$15="Passa",I12,-1)>=IF(Matriz!$D$15="Passa",J12,-1),IF(Matriz!$C$15="Passa",I12,-1)>=IF(Matriz!$E$15="Passa",K12,-1)),$I$5,IF(IF(Matriz!$D$15="Passa",J12,-1)>=IF(Matriz!$E$15="Passa",K12,-1),$J$5,$K$5)) -> Híbrido
A13: 4 | B13: 0.1 | C13: =IF(1=$A13,MAX(0,MIN(1,INDEX(AHP!$I$4:$I$9,$A13)+$B13)),INDEX(AHP!$I$4:$I$9,1)*(1-MAX(0,MIN(1,INDEX(AHP!$I$4:$I$9,$A13)+$B13)))/(1-INDEX(AHP!$I$4:$I$9,$A13))) -> 0.37383933 | D13: =IF(2=$A13,MAX(0,MIN(1,INDEX(AHP!$I$4:$I$9,$A13)+$B13)),INDEX(AHP!$I$4:$I$9,2)*(1-MAX(0,MIN(1,INDEX(AHP!$I$4:$I$9,$A13)+$B13)))/(1-INDEX(AHP!$I$4:$I$9,$A13))) -> 0.16718603 | E13: =IF(3=$A13,MAX(0,MIN(1,INDEX(AHP!$I$4:$I$9,$A13)+$B13)),INDEX(AHP!$I$4:$I$9,3)*(1-MAX(0,MIN(1,INDEX(AHP!$I$4:$I$9,$A13)+$B13)))/(1-INDEX(AHP!$I$4:$I$9,$A13))) -> 0.061464471 | F13: =IF(4=$A13,MAX(0,MIN(1,INDEX(AHP!$I$4:$I$9,$A13)+$B13)),INDEX(AHP!$I$4:$I$9,4)*(1-MAX(0,MIN(1,INDEX(AHP!$I$4:$I$9,$A13)+$B13)))/(1-INDEX(AHP!$I$4:$I$9,$A13))) -> 0.16885967 | G13: =IF(5=$A13,MAX(0,MIN(1,INDEX(AHP!$I$4:$I$9,$A13)+$B13)),INDEX(AHP!$I$4:$I$9,5)*(1-MAX(0,MIN(1,INDEX(AHP!$I$4:$I$9,$A13)+$B13)))/(1-INDEX(AHP!$I$4:$I$9,$A13))) -> 0.061464471 | H13: =IF(6=$A13,MAX(0,MIN(1,INDEX(AHP!$I$4:$I$9,$A13)+$B13)),INDEX(AHP!$I$4:$I$9,6)*(1-MAX(0,MIN(1,INDEX(AHP!$I$4:$I$9,$A13)+$B13)))/(1-INDEX(AHP!$I$4:$I$9,$A13))) -> 0.16718603 | I13: =C13*Matriz!C$5+D13*Matriz!C$6+E13*Matriz!C$7+F13*Matriz!C$8+G13*Matriz!C$9+H13*Matriz!C$10 -> 3.0253445 | J13: =C13*Matriz!D$5+D13*Matriz!D$6+E13*Matriz!D$7+F13*Matriz!D$8+G13*Matriz!D$9+H13*Matriz!D$10 -> 3.45589 | K13: =C13*Matriz!E$5+D13*Matriz!E$6+E13*Matriz!E$7+F13*Matriz!E$8+G13*Matriz!E$9+H13*Matriz!E$10 -> 3.8311403 | L13: =IF(AND(IF(Matriz!$C$15="Passa",I13,-1)>=IF(Matriz!$D$15="Passa",J13,-1),IF(Matriz!$C$15="Passa",I13,-1)>=IF(Matriz!$E$15="Passa",K13,-1)),$I$5,IF(IF(Matriz!$D$15="Passa",J13,-1)>=IF(Matriz!$E$15="Passa",K13,-1),$J$5,$K$5)) -> Híbrido
A14: 5 | B14: -0.1 | C14: =IF(1=$A14,MAX(0,MIN(1,INDEX(AHP!$I$4:$I$9,$A14)+$B14)),INDEX(AHP!$I$4:$I$9,1)*(1-MAX(0,MIN(1,INDEX(AHP!$I$4:$I$9,$A14)+$B14)))/(1-INDEX(AHP!$I$4:$I$9,$A14))) -> 0.44979087 | D14: =IF(2=$A14,MAX(0,MIN(1,INDEX(AHP!$I$4:$I$9,$A14)+$B14)),INDEX(AHP!$I$4:$I$9,2)*(1-MAX(0,MIN(1,INDEX(AHP!$I$4:$I$9,$A14)+$B14)))/(1-INDEX(AHP!$I$4:$I$9,$A14))) -> 0.20115259 | E14: =IF(3=$A14,MAX(0,MIN(1,INDEX(AHP!$I$4:$I$9,$A14)+$B14)),INDEX(AHP!$I$4:$I$9,3)*(1-MAX(0,MIN(1,INDEX(AHP!$I$4:$I$9,$A14)+$B14)))/(1-INDEX(AHP!$I$4:$I$9,$A14))) -> 0.073951977 | F14: =IF(4=$A14,MAX(0,MIN(1,INDEX(AHP!$I$4:$I$9,$A14)+$B14)),INDEX(AHP!$I$4:$I$9,4)*(1-MAX(0,MIN(1,INDEX(AHP!$I$4:$I$9,$A14)+$B14)))/(1-INDEX(AHP!$I$4:$I$9,$A14))) -> 0.073951977 | G14: =IF(5=$A14,MAX(0,MIN(1,INDEX(AHP!$I$4:$I$9,$A14)+$B14)),INDEX(AHP!$I$4:$I$9,5)*(1-MAX(0,MIN(1,INDEX(AHP!$I$4:$I$9,$A14)+$B14)))/(1-INDEX(AHP!$I$4:$I$9,$A14))) -> 0 | H14: =IF(6=$A14,MAX(0,MIN(1,INDEX(AHP!$I$4:$I$9,$A14)+$B14)),INDEX(AHP!$I$4:$I$9,6)*(1-MAX(0,MIN(1,INDEX(AHP!$I$4:$I$9,$A14)+$B14)))/(1-INDEX(AHP!$I$4:$I$9,$A14))) -> 0.20115259 | I14: =C14*Matriz!C$5+D14*Matriz!C$6+E14*Matriz!C$7+F14*Matriz!C$8+G14*Matriz!C$9+H14*Matriz!C$10 -> 2.6241611 | J14: =C14*Matriz!D$5+D14*Matriz!D$6+E14*Matriz!D$7+F14*Matriz!D$8+G14*Matriz!D$9+H14*Matriz!D$10 -> 3.8256298 | K14: =C14*Matriz!E$5+D14*Matriz!E$6+E14*Matriz!E$7+F14*Matriz!E$8+G14*Matriz!E$9+H14*Matriz!E$10 -> 3.926048 | L14: =IF(AND(IF(Matriz!$C$15="Passa",I14,-1)>=IF(Matriz!$D$15="Passa",J14,-1),IF(Matriz!$C$15="Passa",I14,-1)>=IF(Matriz!$E$15="Passa",K14,-1)),$I$5,IF(IF(Matriz!$D$15="Passa",J14,-1)>=IF(Matriz!$E$15="Passa",K14,-1),$J$5,$K$5)) -> Híbrido
A15: 5 | B15: 0.1 | C15: =IF(1=$A15,MAX(0,MIN(1,INDEX(AHP!$I$4:$I$9,$A15)+$B15)),INDEX(AHP!$I$4:$I$9,1)*(1-MAX(0,MIN(1,INDEX(AHP!$I$4:$I$9,$A15)+$B15)))/(1-INDEX(AHP!$I$4:$I$9,$A15))) -> 0.37383933 | D15: =IF(2=$A15,MAX(0,MIN(1,INDEX(AHP!$I$4:$I$9,$A15)+$B15)),INDEX(AHP!$I$4:$I$9,2)*(1-MAX(0,MIN(1,INDEX(AHP!$I$4:$I$9,$A15)+$B15)))/(1-INDEX(AHP!$I$4:$I$9,$A15))) -> 0.16718603 | E15: =IF(3=$A15,MAX(0,MIN(1,INDEX(AHP!$I$4:$I$9,$A15)+$B15)),INDEX(AHP!$I$4:$I$9,3)*(1-MAX(0,MIN(1,INDEX(AHP!$I$4:$I$9,$A15)+$B15)))/(1-INDEX(AHP!$I$4:$I$9,$A15))) -> 0.061464471 | F15: =IF(4=$A15,MAX(0,MIN(1,INDEX(AHP!$I$4:$I$9,$A15)+$B15)),INDEX(AHP!$I$4:$I$9,4)*(1-MAX(0,MIN(1,INDEX(AHP!$I$4:$I$9,$A15)+$B15)))/(1-INDEX(AHP!$I$4:$I$9,$A15))) -> 0.061464471 | G15: =IF(5=$A15,MAX(0,MIN(1,INDEX(AHP!$I$4:$I$9,$A15)+$B15)),INDEX(AHP!$I$4:$I$9,5)*(1-MAX(0,MIN(1,INDEX(AHP!$I$4:$I$9,$A15)+$B15)))/(1-INDEX(AHP!$I$4:$I$9,$A15))) -> 0.16885967 | H15: =IF(6=$A15,MAX(0,MIN(1,INDEX(AHP!$I$4:$I$9,$A15)+$B15)),INDEX(AHP!$I$4:$I$9,6)*(1-MAX(0,MIN(1,INDEX(AHP!$I$4:$I$9,$A15)+$B15)))/(1-INDEX(AHP!$I$4:$I$9,$A15))) -> 0.16718603 | I15: =C15*Matriz!C$5+D15*Matriz!C$6+E15*Matriz!C$7+F15*Matriz!C$8+G15*Matriz!C$9+H15*Matriz!C$10 -> 3.0253445 | J15: =C15*Matriz!D$5+D15*Matriz!D$6+E15*Matriz!D$7+F15*Matriz!D$8+G15*Matriz!D$9+H15*Matriz!D$10 -> 3.3484948 | K15: =C15*Matriz!E$5+D15*Matriz!E$6+E15*Matriz!E$7+F15*Matriz!E$8+G15*Matriz!E$9+H15*Matriz!E$10 -> 3.9385355 | L15: =IF(AND(IF(Matriz!$C$15="Passa",I15,-1)>=IF(Matriz!$D$15="Passa",J15,-1),IF(Matriz!$C$15="Passa",I15,-1)>=IF(Matriz!$E$15="Passa",K15,-1)),$I$5,IF(IF(Matriz!$D$15="Passa",J15,-1)>=IF(Matriz!$E$15="Passa",K15,-1),$J$5,$K$5)) -> Híbrido
A16: 6 | B16: -0.1 | C16: =IF(1=$A16,MAX(0,MIN(1,INDEX(AHP!$I$4:$I$9,$A16)+$B16)),INDEX(AHP!$I$4:$I$9,1)*(1-MAX(0,MIN(1,INDEX(AHP!$I$4:$I$9,$A16)+$B16)))/(1-INDEX(AHP!$I$4:$I$9,$A16))) -> 0.47035269 | D16: =IF(2=$A16,MAX(0,MIN(1,INDEX(AHP!$I$4:$I$9,$A16)+$B16)),INDEX(AHP!$I$4:$I$9,2)*(1-MAX(0,MIN(1,INDEX(AHP!$I$4:$I$9,$A16)+$B16)))/(1-INDEX(AHP!$I$4:$I$9,$A16))) -> 0.21034812 | E16: =IF(3=$A16,MAX(0,MIN(1,INDEX(AHP!$I$4:$I$9,$A16)+$B16)),INDEX(AHP!$I$4:$I$9,3)*(1-MAX(0,MIN(1,INDEX(AHP!$I$4:$I$9,$A16)+$B16)))/(1-INDEX(AHP!$I$4:$I$9,$A16))) -> 0.077332633 | F16: =IF(4=$A16,MAX(0,MIN(1,INDEX(AHP!$I$4:$I$9,$A16)+$B16)),INDEX(AHP!$I$4:$I$9,4)*(1-MAX(0,MIN(1,INDEX(AHP!$I$4:$I$9,$A16)+$B16)))/(1-INDEX(AHP!$I$4:$I$9,$A16))) -> 0.077332633 | G16: =IF(5=$A16,MAX(0,MIN(1,INDEX(AHP!$I$4:$I$9,$A16)+$B16)),INDEX(AHP!$I$4:$I$9,5)*(1-MAX(0,MIN(1,INDEX(AHP!$I$4:$I$9,$A16)+$B16)))/(1-INDEX(AHP!$I$4:$I$9,$A16))) -> 0.077332633 | H16: =IF(6=$A16,MAX(0,MIN(1,INDEX(AHP!$I$4:$I$9,$A16)+$B16)),INDEX(AHP!$I$4:$I$9,6)*(1-MAX(0,MIN(1,INDEX(AHP!$I$4:$I$9,$A16)+$B16)))/(1-INDEX(AHP!$I$4:$I$9,$A16))) -> 0.087301289 | I16: =C16*Matriz!C$5+D16*Matriz!C$6+E16*Matriz!C$7+F16*Matriz!C$8+G16*Matriz!C$9+H16*Matriz!C$10 -> 3.0077389 | J16: =C16*Matriz!D$5+D16*Matriz!D$6+E16*Matriz!D$7+F16*Matriz!D$8+G16*Matriz!D$9+H16*Matriz!D$10 -> 3.4626138 | K16: =C16*Matriz!E$5+D16*Matriz!E$6+E16*Matriz!E$7+F16*Matriz!E$8+G16*Matriz!E$9+H16*Matriz!E$10 -> 3.9226674 | L16: =IF(AND(IF(Matriz!$C$15="Passa",I16,-1)>=IF(Matriz!$D$15="Passa",J16,-1),IF(Matriz!$C$15="Passa",I16,-1)>=IF(Matriz!$E$15="Passa",K16,-1)),$I$5,IF(IF(Matriz!$D$15="Passa",J16,-1)>=IF(Matriz!$E$15="Passa",K16,-1),$J$5,$K$5)) -> Híbrido
A17: 6 | B17: 0.1 | C17: =IF(1=$A17,MAX(0,MIN(1,INDEX(AHP!$I$4:$I$9,$A17)+$B17)),INDEX(AHP!$I$4:$I$9,1)*(1-MAX(0,MIN(1,INDEX(AHP!$I$4:$I$9,$A17)+$B17)))/(1-INDEX(AHP!$I$4:$I$9,$A17))) -> 0.36728414 | D17: =IF(2=$A17,MAX(0,MIN(1,INDEX(AHP!$I$4:$I$9,$A17)+$B17)),INDEX(AHP!$I$4:$I$9,2)*(1-MAX(0,MIN(1,INDEX(AHP!$I$4:$I$9,$A17)+$B17)))/(1-INDEX(AHP!$I$4:$I$9,$A17))) -> 0.16425446 | E17: =IF(3=$A17,MAX(0,MIN(1,INDEX(AHP!$I$4:$I$9,$A17)+$B17)),INDEX(AHP!$I$4:$I$9,3)*(1-MAX(0,MIN(1,INDEX(AHP!$I$4:$I$9,$A17)+$B17)))/(1-INDEX(AHP!$I$4:$I$9,$A17))) -> 0.060386705 | F17: =IF(4=$A17,MAX(0,MIN(1,INDEX(AHP!$I$4:$I$9,$A17)+$B17)),INDEX(AHP!$I$4:$I$9,4)*(1-MAX(0,MIN(1,INDEX(AHP!$I$4:$I$9,$A17)+$B17)))/(1-INDEX(AHP!$I$4:$I$9,$A17))) -> 0.060386705 | G17: =IF(5=$A17,MAX(0,MIN(1,INDEX(AHP!$I$4:$I$9,$A17)+$B17)),INDEX(AHP!$I$4:$I$9,5)*(1-MAX(0,MIN(1,INDEX(AHP!$I$4:$I$9,$A17)+$B17)))/(1-INDEX(AHP!$I$4:$I$9,$A17))) -> 0.060386705 | H17: =IF(6=$A17,MAX(0,MIN(1,INDEX(AHP!$I$4:$I$9,$A17)+$B17)),INDEX(AHP!$I$4:$I$9,6)*(1-MAX(0,MIN(1,INDEX(AHP!$I$4:$I$9,$A17)+$B17)))/(1-INDEX(AHP!$I$4:$I$9,$A17))) -> 0.28730129 | I17: =C17*Matriz!C$5+D17*Matriz!C$6+E17*Matriz!C$7+F17*Matriz!C$8+G17*Matriz!C$9+H17*Matriz!C$10 -> 2.5677823 | J17: =C17*Matriz!D$5+D17*Matriz!D$6+E17*Matriz!D$7+F17*Matriz!D$8+G17*Matriz!D$9+H17*Matriz!D$10 -> 3.7995018 | K17: =C17*Matriz!E$5+D17*Matriz!E$6+E17*Matriz!E$7+F17*Matriz!E$8+G17*Matriz!E$9+H17*Matriz!E$10 -> 3.9396133 | L17: =IF(AND(IF(Matriz!$C$15="Passa",I17,-1)>=IF(Matriz!$D$15="Passa",J17,-1),IF(Matriz!$C$15="Passa",I17,-1)>=IF(Matriz!$E$15="Passa",K17,-1)),$I$5,IF(IF(Matriz!$D$15="Passa",J17,-1)>=IF(Matriz!$E$15="Passa",K17,-1),$J$5,$K$5)) -> Híbrido
A20: Varredura do peso de C2 (capital imobilizado)
A21: Peso de C2 | C21: C1 | D21: C2 | E21: C3 | F21: C4 | G21: C5 | H21: C6 | I21: Centralizado | J21: Descentralizado | K21: Híbrido | L21: Líder (após filtro)
A22: 0 | C22: =IF(1=2,$A22,INDEX(AHP!$I$4:$I$9,1)*(1-$A22)/(1-INDEX(AHP!$I$4:$I$9,2))) -> 0.51534278 | D22: =IF(2=2,$A22,INDEX(AHP!$I$4:$I$9,2)*(1-$A22)/(1-INDEX(AHP!$I$4:$I$9,2))) -> 0 | E22: =IF(3=2,$A22,INDEX(AHP!$I$4:$I$9,3)*(1-$A22)/(1-INDEX(AHP!$I$4:$I$9,2))) -> 0.08472964 | F22: =IF(4=2,$A22,INDEX(AHP!$I$4:$I$9,4)*(1-$A22)/(1-INDEX(AHP!$I$4:$I$9,2))) -> 0.08472964 | G22: =IF(5=2,$A22,INDEX(AHP!$I$4:$I$9,5)*(1-$A22)/(1-INDEX(AHP!$I$4:$I$9,2))) -> 0.08472964 | H22: =IF(6=2,$A22,INDEX(AHP!$I$4:$I$9,6)*(1-$A22)/(1-INDEX(AHP!$I$4:$I$9,2))) -> 0.2304683 | I22: =C22*Matriz!C$5+D22*Matriz!C$6+E22*Matriz!C$7+F22*Matriz!C$8+G22*Matriz!C$9+H22*Matriz!C$10 -> 2.2779095 | J22: =C22*Matriz!D$5+D22*Matriz!D$6+E22*Matriz!D$7+F22*Matriz!D$8+G22*Matriz!D$9+H22*Matriz!D$10 -> 4.2374332 | K22: =C22*Matriz!E$5+D22*Matriz!E$6+E22*Matriz!E$7+F22*Matriz!E$8+G22*Matriz!E$9+H22*Matriz!E$10 -> 3.9152704 | L22: =IF(AND(IF(Matriz!$C$15="Passa",I22,-1)>=IF(Matriz!$D$15="Passa",J22,-1),IF(Matriz!$C$15="Passa",I22,-1)>=IF(Matriz!$E$15="Passa",K22,-1)),$I$5,IF(IF(Matriz!$D$15="Passa",J22,-1)>=IF(Matriz!$E$15="Passa",K22,-1),$J$5,$K$5)) -> Descentralizado
A23: 0.05 | C23: =IF(1=2,$A23,INDEX(AHP!$I$4:$I$9,1)*(1-$A23)/(1-INDEX(AHP!$I$4:$I$9,2))) -> 0.48957564 | D23: =IF(2=2,$A23,INDEX(AHP!$I$4:$I$9,2)*(1-$A23)/(1-INDEX(AHP!$I$4:$I$9,2))) -> 0.05 | E23: =IF(3=2,$A23,INDEX(AHP!$I$4:$I$9,3)*(1-$A23)/(1-INDEX(AHP!$I$4:$I$9,2))) -> 0.080493158 | F23: =IF(4=2,$A23,INDEX(AHP!$I$4:$I$9,4)*(1-$A23)/(1-INDEX(AHP!$I$4:$I$9,2))) -> 0.080493158 | G23: =IF(5=2,$A23,INDEX(AHP!$I$4:$I$9,5)*(1-$A23)/(1-INDEX(AHP!$I$4:$I$9,2))) -> 0.080493158 | H23: =IF(6=2,$A23,INDEX(AHP!$I$4:$I$9,6)*(1-$A23)/(1-INDEX(AHP!$I$4:$I$9,2))) -> 0.21894488 | I23: =C23*Matriz!C$5+D23*Matriz!C$6+E23*Matriz!C$7+F23*Matriz!C$8+G23*Matriz!C$9+H23*Matriz!C$10 -> 2.4140141 | J23: =C23*Matriz!D$5+D23*Matriz!D$6+E23*Matriz!D$7+F23*Matriz!D$8+G23*Matriz!D$9+H23*Matriz!D$10 -> 4.0755616 | K23: =C23*Matriz!E$5+D23*Matriz!E$6+E23*Matriz!E$7+F23*Matriz!E$8+G23*Matriz!E$9+H23*Matriz!E$10 -> 3.9195068 | L23: =IF(AND(IF(Matriz!$C$15="Passa",I23,-1)>=IF(Matriz!$D$15="Passa",J23,-1),IF(Matriz!$C$15="Passa",I23,-1)>=IF(Matriz!$E$15="Passa",K23,-1)),$I$5,IF(IF(Matriz!$D$15="Passa",J23,-1)>=IF(Matriz!$E$15="Passa",K23,-1),$J$5,$K$5)) -> Descentralizado
A24: 0.1 | C24: =IF(1=2,$A24,INDEX(AHP!$I$4:$I$9,1)*(1-$A24)/(1-INDEX(AHP!$I$4:$I$9,2))) -> 0.4638085 | D24: =IF(2=2,$A24,INDEX(AHP!$I$4:$I$9,2)*(1-$A24)/(1-INDEX(AHP!$I$4:$I$9,2))) -> 0.1 | E24: =IF(3=2,$A24,INDEX(AHP!$I$4:$I$9,3)*(1-$A24)/(1-INDEX(AHP!$I$4:$I$9,2))) -> 0.076256676 | F24: =IF(4=2,$A24,INDEX(AHP!$I$4:$I$9,4)*(1-$A24)/(1-INDEX(AHP!$I$4:$I$9,2))) -> 0.076256676 | G24: =IF(5=2,$A24,INDEX(AHP!$I$4:$I$9,5)*(1-$A24)/(1-INDEX(AHP!$I$4:$I$9,2))) -> 0.076256676 | H24: =IF(6=2,$A24,INDEX(AHP!$I$4:$I$9,6)*(1-$A24)/(1-INDEX(AHP!$I$4:$I$9,2))) -> 0.20742147 | I24: =C24*Matriz!C$5+D24*Matriz!C$6+E24*Matriz!C$7+F24*Matriz!C$8+G24*Matriz!C$9+H24*Matriz!C$10 -> 2.5501186 | J24: =C24*Matriz!D$5+D24*Matriz!D$6+E24*Matriz!D$7+F24*Matriz!D$8+G24*Matriz!D$9+H24*Matriz!D$10 -> 3.9136899 | K24: =C24*Matriz!E$5+D24*Matriz!E$6+E24*Matriz!E$7+F24*Matriz!E$8+G24*Matriz!E$9+H24*Matriz!E$10 -> 3.9237433 | L24: =IF(AND(IF(Matriz!$C$15="Passa",I24,-1)>=IF(Matriz!$D$15="Passa",J24,-1),IF(Matriz!$C$15="Passa",I24,-1)>=IF(Matriz!$E$15="Passa",K24,-1)),$I$5,IF(IF(Matriz!$D$15="Passa",J24,-1)>=IF(Matriz!$E$15="Passa",K24,-1),$J$5,$K$5)) -> Híbrido
A25: 0.15 | C25: =IF(1=2,$A25,INDEX(AHP!$I$4:$I$9,1)*(1-$A25)/(1-INDEX(AHP!$I$4:$I$9,2))) -> 0.43804137 | D25: =IF(2=2,$A25,INDEX(AHP!$I$4:$I$9,2)*(1-$A25)/(1-INDEX(AHP!$I$4:$I$9,2))) -> 0.15 | E25: =IF(3=2,$A25,INDEX(AHP!$I$4:$I$9,3)*(1-$A25)/(1-INDEX(AHP!$I$4:$I$9,2))) -> 0.072020194 | F25: =IF(4=2,$A25,INDEX(AHP!$I$4:$I$9,4)*(1-$A25)/(1-INDEX(AHP!$I$4:$I$9,2))) -> 0.072020194 | G25: =IF(5=2,$A25,INDEX(AHP!$I$4:$I$9,5)*(1-$A25)/(1-INDEX(AHP!$I$4:$I$9,2))) -> 0.072020194 | H25: =IF(6=2,$A25,INDEX(AHP!$I$4:$I$9,6)*(1-$A25)/(1-INDEX(AHP!$I$4:$I$9,2))) -> 0.19589805 | I25: =C25*Matriz!C$5+D25*Matriz!C$6+E25*Matriz!C$7+F25*Matriz!C$8+G25*Matriz!C$9+H25*Matriz!C$10 -> 2.6862231 | J25: =C25*Matriz!D$5+D25*Matriz!D$6+E25*Matriz!D$7+F25*Matriz!D$8+G25*Matriz!D$9+H25*Matriz!D$10 -> 3.7518183 | K25: =C25*Matriz!E$5+D25*Matriz!E$6+E25*Matriz!E$7+F25*Matriz!E$8+G25*Matriz!E$9+H25*Matriz!E$10 -> 3.9279798 | L25: =IF(AND(IF(Matriz!$C$15="Passa",I25,-1)>=IF(Matriz!$D$15="Passa",J25,-1),IF(Matriz!$C$15="Passa",I25,-1)>=IF(Matriz!$E$15="Passa",K25,-1)),$I$5,IF(IF(Matriz!$D$15="Passa",J25,-1)>=IF(Matriz!$E$15="Passa",K25,-1),$J$5,$K$5)) -> Híbrido
A26: 0.2 | C26: =IF(1=2,$A26,INDEX(AHP!$I$4:$I$9,1)*(1-$A26)/(1-INDEX(AHP!$I$4:$I$9,2))) -> 0.41227423 | D26: =IF(2=2,$A26,INDEX(AHP!$I$4:$I$9,2)*(1-$A26)/(1-INDEX(AHP!$I$4:$I$9,2))) -> 0.2 | E26: =IF(3=2,$A26,INDEX(AHP!$I$4:$I$9,3)*(1-$A26)/(1-INDEX(AHP!$I$4:$I$9,2))) -> 0.067783712 | F26: =IF(4=2,$A26,INDEX(AHP!$I$4:$I$9,4)*(1-$A26)/(1-INDEX(AHP!$I$4:$I$9,2))) -> 0.067783712 | G26: =IF(5=2,$A26,INDEX(AHP!$I$4:$I$9,5)*(1-$A26)/(1-INDEX(AHP!$I$4:$I$9,2))) -> 0.067783712 | H26: =IF(6=2,$A26,INDEX(AHP!$I$4:$I$9,6)*(1-$A26)/(1-INDEX(AHP!$I$4:$I$9,2))) -> 0.18437464 | I26: =C26*Matriz!C$5+D26*Matriz!C$6+E26*Matriz!C$7+F26*Matriz!C$8+G26*Matriz!C$9+H26*Matriz!C$10 -> 2.8223276 | J26: =C26*Matriz!D$5+D26*Matriz!D$6+E26*Matriz!D$7+F26*Matriz!D$8+G26*Matriz!D$9+H26*Matriz!D$10 -> 3.5899466 | K26: =C26*Matriz!E$5+D26*Matriz!E$6+E26*Matriz!E$7+F26*Matriz!E$8+G26*Matriz!E$9+H26*Matriz!E$10 -> 3.9322163 | L26: =IF(AND(IF(Matriz!$C$15="Passa",I26,-1)>=IF(Matriz!$D$15="Passa",J26,-1),IF(Matriz!$C$15="Passa",I26,-1)>=IF(Matriz!$E$15="Passa",K26,-1)),$I$5,IF(IF(Matriz!$D$15="Passa",J26,-1)>=IF(Matriz!$E$15="Passa",K26,-1),$J$5,$K$5)) -> Híbrido
A27: 0.25 | C27: =IF(1=2,$A27,INDEX(AHP!$I$4:$I$9,1)*(1-$A27)/(1-INDEX(AHP!$I$4:$I$9,2))) -> 0.38650709 | D27: =IF(2=2,$A27,INDEX(AHP!$I$4:$I$9,2)*(1-$A27)/(1-INDEX(AHP!$I$4:$I$9,2))) -> 0.25 | E27: =IF(3=2,$A27,INDEX(AHP!$I$4:$I$9,3)*(1-$A27)/(1-INDEX(AHP!$I$4:$I$9,2))) -> 0.06354723 | F27: =IF(4=2,$A27,INDEX(AHP!$I$4:$I$9,4)*(1-$A27)/(1-INDEX(AHP!$I$4:$I$9,2))) -> 0.06354723 | G27: =IF(5=2,$A27,INDEX(AHP!$I$4:$I$9,5)*(1-$A27)/(1-INDEX(AHP!$I$4:$I$9,2))) -> 0.06354723 | H27: =IF(6=2,$A27,INDEX(AHP!$I$4:$I$9,6)*(1-$A27)/(1-INDEX(AHP!$I$4:$I$9,2))) -> 0.17285122 | I27: =C27*Matriz!C$5+D27*Matriz!C$6+E27*Matriz!C$7+F27*Matriz!C$8+G27*Matriz!C$9+H27*Matriz!C$10 -> 2.9584322 | J27: =C27*Matriz!D$5+D27*Matriz!D$6+E27*Matriz!D$7+F27*Matriz!D$8+G27*Matriz!D$9+H27*Matriz!D$10 -> 3.4280749 | K27: =C27*Matriz!E$5+D27*Matriz!E$6+E27*Matriz!E$7+F27*Matriz!E$8+G27*Matriz!E$9+H27*Matriz!E$10 -> 3.9364528 | L27: =IF(AND(IF(Matriz!$C$15="Passa",I27,-1)>=IF(Matriz!$D$15="Passa",J27,-1),IF(Matriz!$C$15="Passa",I27,-1)>=IF(Matriz!$E$15="Passa",K27,-1)),$I$5,IF(IF(Matriz!$D$15="Passa",J27,-1)>=IF(Matriz!$E$15="Passa",K27,-1),$J$5,$K$5)) -> Híbrido
A28: 0.3 | C28: =IF(1=2,$A28,INDEX(AHP!$I$4:$I$9,1)*(1-$A28)/(1-INDEX(AHP!$I$4:$I$9,2))) -> 0.36073995 | D28: =IF(2=2,$A28,INDEX(AHP!$I$4:$I$9,2)*(1-$A28)/(1-INDEX(AHP!$I$4:$I$9,2))) -> 0.3 | E28: =IF(3=2,$A28,INDEX(AHP!$I$4:$I$9,3)*(1-$A28)/(1-INDEX(AHP!$I$4:$I$9,2))) -> 0.059310748 | F28: =IF(4=2,$A28,INDEX(AHP!$I$4:$I$9,4)*(1-$A28)/(1-INDEX(AHP!$I$4:$I$9,2))) -> 0.059310748 | G28: =IF(5=2,$A28,INDEX(AHP!$I$4:$I$9,5)*(1-$A28)/(1-INDEX(AHP!$I$4:$I$9,2))) -> 0.059310748 | H28: =IF(6=2,$A28,INDEX(AHP!$I$4:$I$9,6)*(1-$A28)/(1-INDEX(AHP!$I$4:$I$9,2))) -> 0.16132781 | I28: =C28*Matriz!C$5+D28*Matriz!C$6+E28*Matriz!C$7+F28*Matriz!C$8+G28*Matriz!C$9+H28*Matriz!C$10 -> 3.0945367 | J28: =C28*Matriz!D$5+D28*Matriz!D$6+E28*Matriz!D$7+F28*Matriz!D$8+G28*Matriz!D$9+H28*Matriz!D$10 -> 3.2662033 | K28: =C28*Matriz!E$5+D28*Matriz!E$6+E28*Matriz!E$7+F28*Matriz!E$8+G28*Matriz!E$9+H28*Matriz!E$10 -> 3.9406893 | L28: =IF(AND(IF(Matriz!$C$15="Passa",I28,-1)>=IF(Matriz!$D$15="Passa",J28,-1),IF(Matriz!$C$15="Passa",I28,-1)>=IF(Matriz!$E$15="Passa",K28,-1)),$I$5,IF(IF(Matriz!$D$15="Passa",J28,-1)>=IF(Matriz!$E$15="Passa",K28,-1),$J$5,$K$5)) -> Híbrido
A29: 0.35 | C29: =IF(1=2,$A29,INDEX(AHP!$I$4:$I$9,1)*(1-$A29)/(1-INDEX(AHP!$I$4:$I$9,2))) -> 0.33497281 | D29: =IF(2=2,$A29,INDEX(AHP!$I$4:$I$9,2)*(1-$A29)/(1-INDEX(AHP!$I$4:$I$9,2))) -> 0.35 | E29: =IF(3=2,$A29,INDEX(AHP!$I$4:$I$9,3)*(1-$A29)/(1-INDEX(AHP!$I$4:$I$9,2))) -> 0.055074266 | F29: =IF(4=2,$A29,INDEX(AHP!$I$4:$I$9,4)*(1-$A29)/(1-INDEX(AHP!$I$4:$I$9,2))) -> 0.055074266 | G29: =IF(5=2,$A29,INDEX(AHP!$I$4:$I$9,5)*(1-$A29)/(1-INDEX(AHP!$I$4:$I$9,2))) -> 0.055074266 | H29: =IF(6=2,$A29,INDEX(AHP!$I$4:$I$9,6)*(1-$A29)/(1-INDEX(AHP!$I$4:$I$9,2))) -> 0.14980439 | I29: =C29*Matriz!C$5+D29*Matriz!C$6+E29*Matriz!C$7+F29*Matriz!C$8+G29*Matriz!C$9+H29*Matriz!C$10 -> 3.2306412 | J29: =C29*Matriz!D$5+D29*Matriz!D$6+E29*Matriz!D$7+F29*Matriz!D$8+G29*Matriz!D$9+H29*Matriz!D$10 -> 3.1043316 | K29: =C29*Matriz!E$5+D29*Matriz!E$6+E29*Matriz!E$7+F29*Matriz!E$8+G29*Matriz!E$9+H29*Matriz!E$10 -> 3.9449257 | L29: =IF(AND(IF(Matriz!$C$15="Passa",I29,-1)>=IF(Matriz!$D$15="Passa",J29,-1),IF(Matriz!$C$15="Passa",I29,-1)>=IF(Matriz!$E$15="Passa",K29,-1)),$I$5,IF(IF(Matriz!$D$15="Passa",J29,-1)>=IF(Matriz!$E$15="Passa",K29,-1),$J$5,$K$5)) -> Híbrido
A30: 0.4 | C30: =IF(1=2,$A30,INDEX(AHP!$I$4:$I$9,1)*(1-$A30)/(1-INDEX(AHP!$I$4:$I$9,2))) -> 0.30920567 | D30: =IF(2=2,$A30,INDEX(AHP!$I$4:$I$9,2)*(1-$A30)/(1-INDEX(AHP!$I$4:$I$9,2))) -> 0.4 | E30: =IF(3=2,$A30,INDEX(AHP!$I$4:$I$9,3)*(1-$A30)/(1-INDEX(AHP!$I$4:$I$9,2))) -> 0.050837784 | F30: =IF(4=2,$A30,INDEX(AHP!$I$4:$I$9,4)*(1-$A30)/(1-INDEX(AHP!$I$4:$I$9,2))) -> 0.050837784 | G30: =IF(5=2,$A30,INDEX(AHP!$I$4:$I$9,5)*(1-$A30)/(1-INDEX(AHP!$I$4:$I$9,2))) -> 0.050837784 | H30: =IF(6=2,$A30,INDEX(AHP!$I$4:$I$9,6)*(1-$A30)/(1-INDEX(AHP!$I$4:$I$9,2))) -> 0.13828098 | I30: =C30*Matriz!C$5+D30*Matriz!C$6+E30*Matriz!C$7+F30*Matriz!C$8+G30*Matriz!C$9+H30*Matriz!C$10 -> 3.3667457 | J30: =C30*Matriz!D$5+D30*Matriz!D$6+E30*Matriz!D$7+F30*Matriz!D$8+G30*Matriz!D$9+H30*Matriz!D$10 -> 2.9424599 | K30: =C30*Matriz!E$5+D30*Matriz!E$6+E30*Matriz!E$7+F30*Matriz!E$8+G30*Matriz!E$9+H30*Matriz!E$10 -> 3.9491622 | L30: =IF(AND(IF(Matriz!$C$15="Passa",I30,-1)>=IF(Matriz!$D$15="Passa",J30,-1),IF(Matriz!$C$15="Passa",I30,-1)>=IF(Matriz!$E$15="Passa",K30,-1)),$I$5,IF(IF(Matriz!$D$15="Passa",J30,-1)>=IF(Matriz!$E$15="Passa",K30,-1),$J$5,$K$5)) -> Híbrido
A31: 0.45 | C31: =IF(1=2,$A31,INDEX(AHP!$I$4:$I$9,1)*(1-$A31)/(1-INDEX(AHP!$I$4:$I$9,2))) -> 0.28343853 | D31: =IF(2=2,$A31,INDEX(AHP!$I$4:$I$9,2)*(1-$A31)/(1-INDEX(AHP!$I$4:$I$9,2))) -> 0.45 | E31: =IF(3=2,$A31,INDEX(AHP!$I$4:$I$9,3)*(1-$A31)/(1-INDEX(AHP!$I$4:$I$9,2))) -> 0.046601302 | F31: =IF(4=2,$A31,INDEX(AHP!$I$4:$I$9,4)*(1-$A31)/(1-INDEX(AHP!$I$4:$I$9,2))) -> 0.046601302 | G31: =IF(5=2,$A31,INDEX(AHP!$I$4:$I$9,5)*(1-$A31)/(1-INDEX(AHP!$I$4:$I$9,2))) -> 0.046601302 | H31: =IF(6=2,$A31,INDEX(AHP!$I$4:$I$9,6)*(1-$A31)/(1-INDEX(AHP!$I$4:$I$9,2))) -> 0.12675756 | I31: =C31*Matriz!C$5+D31*Matriz!C$6+E31*Matriz!C$7+F31*Matriz!C$8+G31*Matriz!C$9+H31*Matriz!C$10 -> 3.5028502 | J31: =C31*Matriz!D$5+D31*Matriz!D$6+E31*Matriz!D$7+F31*Matriz!D$8+G31*Matriz!D$9+H31*Matriz!D$10 -> 2.7805883 | K31: =C31*Matriz!E$5+D31*Matriz!E$6+E31*Matriz!E$7+F31*Matriz!E$8+G31*Matriz!E$9+H31*Matriz!E$10 -> 3.9533987 | L31: =IF(AND(IF(Matriz!$C$15="Passa",I31,-1)>=IF(Matriz!$D$15="Passa",J31,-1),IF(Matriz!$C$15="Passa",I31,-1)>=IF(Matriz!$E$15="Passa",K31,-1)),$I$5,IF(IF(Matriz!$D$15="Passa",J31,-1)>=IF(Matriz!$E$15="Passa",K31,-1),$J$5,$K$5)) -> Híbrido
A32: 0.5 | C32: =IF(1=2,$A32,INDEX(AHP!$I$4:$I$9,1)*(1-$A32)/(1-INDEX(AHP!$I$4:$I$9,2))) -> 0.25767139 | D32: =IF(2=2,$A32,INDEX(AHP!$I$4:$I$9,2)*(1-$A32)/(1-INDEX(AHP!$I$4:$I$9,2))) -> 0.5 | E32: =IF(3=2,$A32,INDEX(AHP!$I$4:$I$9,3)*(1-$A32)/(1-INDEX(AHP!$I$4:$I$9,2))) -> 0.04236482 | F32: =IF(4=2,$A32,INDEX(AHP!$I$4:$I$9,4)*(1-$A32)/(1-INDEX(AHP!$I$4:$I$9,2))) -> 0.04236482 | G32: =IF(5=2,$A32,INDEX(AHP!$I$4:$I$9,5)*(1-$A32)/(1-INDEX(AHP!$I$4:$I$9,2))) -> 0.04236482 | H32: =IF(6=2,$A32,INDEX(AHP!$I$4:$I$9,6)*(1-$A32)/(1-INDEX(AHP!$I$4:$I$9,2))) -> 0.11523415 | I32: =C32*Matriz!C$5+D32*Matriz!C$6+E32*Matriz!C$7+F32*Matriz!C$8+G32*Matriz!C$9+H32*Matriz!C$10 -> 3.6389548 | J32: =C32*Matriz!D$5+D32*Matriz!D$6+E32*Matriz!D$7+F32*Matriz!D$8+G32*Matriz!D$9+H32*Matriz!D$10 -> 2.6187166 | K32: =C32*Matriz!E$5+D32*Matriz!E$6+E32*Matriz!E$7+F32*Matriz!E$8+G32*Matriz!E$9+H32*Matriz!E$10 -> 3.9576352 | L32: =IF(AND(IF(Matriz!$C$15="Passa",I32,-1)>=IF(Matriz!$D$15="Passa",J32,-1),IF(Matriz!$C$15="Passa",I32,-1)>=IF(Matriz!$E$15="Passa",K32,-1)),$I$5,IF(IF(Matriz!$D$15="Passa",J32,-1)>=IF(Matriz!$E$15="Passa",K32,-1),$J$5,$K$5)) -> Híbrido
A33: 0.55 | C33: =IF(1=2,$A33,INDEX(AHP!$I$4:$I$9,1)*(1-$A33)/(1-INDEX(AHP!$I$4:$I$9,2))) -> 0.23190425 | D33: =IF(2=2,$A33,INDEX(AHP!$I$4:$I$9,2)*(1-$A33)/(1-INDEX(AHP!$I$4:$I$9,2))) -> 0.55 | E33: =IF(3=2,$A33,INDEX(AHP!$I$4:$I$9,3)*(1-$A33)/(1-INDEX(AHP!$I$4:$I$9,2))) -> 0.038128338 | F33: =IF(4=2,$A33,INDEX(AHP!$I$4:$I$9,4)*(1-$A33)/(1-INDEX(AHP!$I$4:$I$9,2))) -> 0.038128338 | G33: =IF(5=2,$A33,INDEX(AHP!$I$4:$I$9,5)*(1-$A33)/(1-INDEX(AHP!$I$4:$I$9,2))) -> 0.038128338 | H33: =IF(6=2,$A33,INDEX(AHP!$I$4:$I$9,6)*(1-$A33)/(1-INDEX(AHP!$I$4:$I$9,2))) -> 0.10371073 | I33: =C33*Matriz!C$5+D33*Matriz!C$6+E33*Matriz!C$7+F33*Matriz!C$8+G33*Matriz!C$9+H33*Matriz!C$10 -> 3.7750593 | J33: =C33*Matriz!D$5+D33*Matriz!D$6+E33*Matriz!D$7+F33*Matriz!D$8+G33*Matriz!D$9+H33*Matriz!D$10 -> 2.456845 | K33: =C33*Matriz!E$5+D33*Matriz!E$6+E33*Matriz!E$7+F33*Matriz!E$8+G33*Matriz!E$9+H33*Matriz!E$10 -> 3.9618717 | L33: =IF(AND(IF(Matriz!$C$15="Passa",I33,-1)>=IF(Matriz!$D$15="Passa",J33,-1),IF(Matriz!$C$15="Passa",I33,-1)>=IF(Matriz!$E$15="Passa",K33,-1)),$I$5,IF(IF(Matriz!$D$15="Passa",J33,-1)>=IF(Matriz!$E$15="Passa",K33,-1),$J$5,$K$5)) -> Híbrido
... A38: 0.8 | C38: =IF(1=2,$A38,INDEX(AHP!$I$4:$I$9,1)*(1-$A38)/(1-INDEX(AHP!$I$4:$I$9,2))) -> 0.10306856 | D38: =IF(2=2,$A38,INDEX(AHP!$I$4:$I$9,2)*(1-$A38)/(1-INDEX(AHP!$I$4:$I$9,2))) -> 0.8 | E38: =IF(3=2,$A38,INDEX(AHP!$I$4:$I$9,3)*(1-$A38)/(1-INDEX(AHP!$I$4:$I$9,2))) -> 0.016945928 | F38: =IF(4=2,$A38,INDEX(AHP!$I$4:$I$9,4)*(1-$A38)/(1-INDEX(AHP!$I$4:$I$9,2))) -> 0.016945928 | G38: =IF(5=2,$A38,INDEX(AHP!$I$4:$I$9,5)*(1-$A38)/(1-INDEX(AHP!$I$4:$I$9,2))) -> 0.016945928 | H38: =IF(6=2,$A38,INDEX(AHP!$I$4:$I$9,6)*(1-$A38)/(1-INDEX(AHP!$I$4:$I$9,2))) -> 0.04609366 | I38: =C38*Matriz!C$5+D38*Matriz!C$6+E38*Matriz!C$7+F38*Matriz!C$8+G38*Matriz!C$9+H38*Matriz!C$10 -> 4.4555819 | J38: =C38*Matriz!D$5+D38*Matriz!D$6+E38*Matriz!D$7+F38*Matriz!D$8+G38*Matriz!D$9+H38*Matriz!D$10 -> 1.6474866 | K38: =C38*Matriz!E$5+D38*Matriz!E$6+E38*Matriz!E$7+F38*Matriz!E$8+G38*Matriz!E$9+H38*Matriz!E$10 -> 3.9830541 | L38: =IF(AND(IF(Matriz!$C$15="Passa",I38,-1)>=IF(Matriz!$D$15="Passa",J38,-1),IF(Matriz!$C$15="Passa",I38,-1)>=IF(Matriz!$E$15="Passa",K38,-1)),$I$5,IF(IF(Matriz!$D$15="Passa",J38,-1)>=IF(Matriz!$E$15="Passa",K38,-1),$J$5,$K$5)) -> Híbrido
A40: No cenário base, o Centralizado não passa no filtro; seus resultados aparecem apenas como referência.
